Breaking Issues:
This happens very, very frequently, and is very breaking for any real use of the cluster:
Intermittent failure to mount devices causing pod's to not get past "ContainerInitializing" stage:
17m         Warning   FailedMount              pod/redis-worker             MountVolume.MountDevice failed for volume "pvc-508d02f6-d04a-4782-b8d7-9a3f8dfdb509" : rpc error: code = DeadlineEx
ceeded desc = context deadline exceeded

Intermittent failure for DNS to resolve inside pods.  Will work for some identical pods inside a job, not others.  Sometimes fails for individual pods.
REDIS EXAMPLE:
redis.exceptions.ConnectionError: Error -2 connecting to redis:6379. Name or service not known.

RABBITMQ EXAMPLE:
Traceback (most recent call last):
  File "/kube/home/git/gefEnvSES/processing.py", line 45, in <module>
    main()
  File "/kube/home/git/gefEnvSES/processing.py", line 33, in main
    connection = pika.BlockingConnection(
                 ^^^^^^^^^^^^^^^^^^^^^^^^
  File "/kube/home/.envs/gefSES/lib/python3.12/site-packages/pika/adapters/blocking_connection.py", line 360, in __init__
    self._impl = self._create_connection(parameters, _impl_class)
                 ^^^^^^^^^^^^^^^^^^^^^^^^^^^^^^^^^^^^^^^^^^^^^^^^
  File "/kube/home/.envs/gefSES/lib/python3.12/site-packages/pika/adapters/blocking_connection.py", line 451, in _create_connection
    raise self._reap_last_connection_workflow_error(error)
  File "/kube/home/.envs/gefSES/lib/python3.12/site-packages/pika/adapters/utils/selector_ioloop_adapter.py", line 565, in _resolve
    result = socket.getaddrinfo(self._host, self._port, self._family,
             ^^^^^^^^^^^^^^^^^^^^^^^^^^^^^^^^^^^^^^^^^^^^^^^^^^^^^^^^
  File "/kube/home/.envs/gefSES/lib/python3.12/socket.py", line 963, in getaddrinfo
    for res in _socket.getaddrinfo(host, port, family, type, proto, flags):
               ^^^^^^^^^^^^^^^^^^^^^^^^^^^^^^^^^^^^^^^^^^^^^^^^^^^^^^^^^^^
socket.gaierror: [Errno -2] Name or service not known


Intermittend failure for volumes to attach - this normally resolves itself after a while, but takes at least ~20 seconds:
4m28s       Warning   FailedAttachVolume       pod/redis-worker-job-f9l9k   AttachVolume.Attach failed for volume "pvc-508d02f6-d04a-4782-b8d7-9a3f8dfdb509" : rpc error: code = NotFound desc = node w07.geo.sciclone.wm.edu not found

